Workbook

Sheet Hoja1
A1: PEDIDOS GARMONT
A2: FECHA | B2: PRODUCTO | C2: CODIGO | D2: CANTIDAD | H2: CAN. TOTAL | I2: PCR | J2: IVA 21% | K2: PRECIO | L2: TOTAL C/IVA | M2: TOTAL S/IVA | N2: PRECIO VENTA | O2: TOTAL | R2: VENTAS | U2: REGALO | V2: STOCK | W2: PRECIO | X2: DESCUENTO | Y2: TOTAL | AA2: STOCK
D3: Talle Unico | E3: S | F3: M | G3: L | R3: S | S3: M | T3: L | AA3: S | AB3: M | AC3: L
A4: 46059 | B4: Bolso Logo MISTEGA | C4: AC2030 | D4: 10 | H4: 10 | I4: 59295 | J4: =SUM(I4*0.21) -> 12451.95 | K4: =SUM(I4:J4) -> 71746.95 | L4: =SUM(H4*K4) -> 717469.5 | M4: =SUM(H4*I4) -> 592950 | N4: 140000 | O4: =SUM(N4*H4) -> 1400000 | S4: 10 | W4: 80000 | Y4: 910000
A5: 46059 | B5: Bolso Logo TRIONX | C5: AC2030 | D5: 10 | E5: 10 | H5: 10 | I5: 59295 | J5: =SUM(I5*0.21) -> 12451.95 | K5: =SUM(I5:J5) -> 71746.95 | L5: =SUM(H5*K5) -> 717469.5 | M5: =SUM(H5*I5) -> 592950 | N5: 140000 | O5: =SUM(N5*H5) -> 1400000 | S5: 1 | U5: 1 | V5: =SUM(H5-(S5+U5)) -> 8 | W5: 140000 | Y5: =SUM(W5*S5) -> 140000
A6: 46059 | B6: Campera Pumori Hombre Negra | C6: SR4143 | D6: 0 | E6: 10 | F6: 14 | G6: 4 | H6: =SUM(E6+F6+G6) -> 28 | I6: 128900 | J6: =SUM(I6*0.21) -> 27069 | K6: =SUM(I6:J6) -> 155969 | L6: =SUM(H6*K6) -> 4367132 | M6: =SUM(H6*I6) -> 3609200 | N6: 260000 | O6: =SUM(N6*H6) -> 7280000 | R6: 1 | V6: =SUM(H6-(R6+S6+T6)) -> 27 | W6: 260000 | Y6: =SUM(W6*(R6+S6+T6)) -> 260000
A7: 46059 | B7: Campera Pumori Hombre Roja | C7: SR4143 | D7: 0 | E7: 4 | F7: 6 | G7: 2 | H7: =SUM(E7+F7+G7) -> 12 | I7: 128900 | J7: =SUM(I7*0.21) -> 27069 | K7: =SUM(I7:J7) -> 155969 | L7: =SUM(H7*K7) -> 1871628 | M7: =SUM(H7*I7) -> 1546800 | N7: 260000 | O7: =SUM(N7*H7) -> 3120000 | S7: 1 | V7: =SUM(H7-(R7+S7+T7)) -> 11 | W7: 260000 | Y7: =SUM(W7*(R7+S7+T7)) -> 260000
A8: 46059 | B8: Campera Pumori Mujer Negra | C8: SR4144 | D8: 0 | E8: 3 | F8: 3 | G8: 0 | H8: =SUM(E8+F8+G8) -> 6 | I8: 128900 | J8: =SUM(I8*0.21) -> 27069 | K8: =SUM(I8:J8) -> 155969 | L8: =SUM(H8*K8) -> 935814 | M8: =SUM(H8*I8) -> 773400 | N8: 260000 | O8: =SUM(N8*H8) -> 1560000 | V8: =SUM(H8-(R8+S8+T8)) -> 6 | W8: 260000 | Y8: =SUM(W8*(R8+S8+T8)) -> 0
A9: 46059 | B9: Campera Pumori Mujer Salmon | C9: SR4144 | D9: 0 | E9: 3 | F9: 3 | G9: 0 | H9: =SUM(E9+F9+G9) -> 6 | I9: 128900 | J9: =SUM(I9*0.21) -> 27069 | K9: =SUM(I9:J9) -> 155969 | L9: =SUM(H9*K9) -> 935814 | M9: =SUM(H9*I9) -> 773400 | N9: 260000 | O9: =SUM(N9*H9) -> 1560000 | V9: =SUM(H9-(R9+S9+T9)) -> 6 | W9: 260000 | Y9: =SUM(W9*(R9+S9+T9)) -> 0
A10: 46059 | B10: Remera Peñon Colorado Hombre Azul | C10: SR6050 | D10: 0 | E10: 1 | F10: 5 | G10: 2 | H10: =SUM(E10+F10+G10) -> 8 | I10: 20000 | J10: =SUM(I10*0.21) -> 4200 | K10: =SUM(I10:J10) -> 24200 | L10: =SUM(H10*K10) -> 193600 | M10: =SUM(H10*I10) -> 160000 | N10: 40000 | O10: =SUM(N10*H10) -> 320000 | V10: =SUM(H10-(R10+S10+T10)) -> 8 | W10: 260000 | Y10: =SUM(W10*(R10+S10+T10)) -> 0
A11: 46059 | B11: Remera Peñon Colorado Hombre Gris | C11: SR6050 | D11: 0 | E11: 1 | F11: 5 | G11: 2 | H11: =SUM(E11+F11+G11) -> 8 | I11: 20000 | J11: =SUM(I11*0.21) -> 4200 | K11: =SUM(I11:J11) -> 24200 | L11: =SUM(H11*K11) -> 193600 | M11: =SUM(H11*I11) -> 160000 | N11: 40000 | O11: =SUM(N11*H11) -> 320000 | V11: =SUM(H11-(R11+S11+T11)) -> 8 | W11: 260000 | Y11: =SUM(W11*(R11+S11+T11)) -> 0
A12: 46059 | B12: Remera Peñon Colorado Hombre terracota | C12: SR6050 | D12: 0 | E12: 2 | F12: 4 | G12: 2 | H12: =SUM(E12+F12+G12) -> 8 | I12: 20000 | J12: =SUM(I12*0.21) -> 4200 | K12: =SUM(I12:J12) -> 24200 | L12: =SUM(H12*K12) -> 193600 | M12: =SUM(H12*I12) -> 160000 | N12: 40000 | O12: =SUM(N12*H12) -> 320000 | V12: =SUM(H12-(R12+S12+T12)) -> 8 | W12: 260000 | Y12: =SUM(W12*(R12+S12+T12)) -> 0
A13: 46059 | B13: Remera Peñon Colorado Mujer Rosa | C13: SR6051 | D13: 0 | E13: 3 | F13: 4 | G13: 1 | H13: =SUM(E13+F13+G13) -> 8 | I13: 20000 | J13: =SUM(I13*0.21) -> 4200 | K13: =SUM(I13:J13) -> 24200 | L13: =SUM(H13*K13) -> 193600 | M13: =SUM(H13*I13) -> 160000 | N13: 40000 | O13: =SUM(N13*H13) -> 320000 | V13: =SUM(H13-(R13+S13+T13)) -> 8 | W13: 260000 | Y13: =SUM(W13*(R13+S13+T13)) -> 0
A14: 46059 | B14: Remera Peñon Colorado Mujer Gris | C14: SR6051 | D14: 0 | E14: 3 | F14: 4 | G14: 1 | H14: =SUM(E14+F14+G14) -> 8 | I14: 20000 | J14: =SUM(I14*0.21) -> 4200 | K14: =SUM(I14:J14) -> 24200 | L14: =SUM(H14*K14) -> 193600 | M14: =SUM(H14*I14) -> 160000 | N14: 40000 | O14: =SUM(N14*H14) -> 320000 | V14: =SUM(H14-(R14+S14+T14)) -> 8 | W14: 260000 | Y14: =SUM(W14*(R14+S14+T14)) -> 0
A15: 46059 | B15: Remera Peñon Colorado Mujer Terracota | C15: SR6051 | D15: 0 | E15: 3 | F15: 4 | G15: 1 | H15: =SUM(E15+F15+G15) -> 8 | I15: 20000 | J15: =SUM(I15*0.21) -> 4200 | K15: =SUM(I15:J15) -> 24200 | L15: =SUM(H15*K15) -> 193600 | M15: =SUM(H15*I15) -> 160000 | N15: 40000 | O15: =SUM(N15*H15) -> 320000 | V15: =SUM(H15-(R15+S15+T15)) -> 8 | W15: 260000 | Y15: =SUM(W15*(R15+S15+T15)) -> 0
I16: =SUM(I4:I15) -> 754190 | K16: =SUM(K4:K15) -> 912569.9 | L16: =SUM(L4:L15) -> 10706927 | M16: =SUM(M4:M15) -> 8848700 | N16: =SUM(N4:N15) -> 1560000 | O16: =SUM(O4:O15) -> 18240000
A17: PEDIDOS PISTA
C18: CODIGO | D18: CANTIDAD | H18: CAN. TOTAL | I18: PCR | J18: IVA 21% | K18: PRECIO | L18: TOTAL C/IVA | M18: TOTAL S/IVA | N18: PRECIO VENTA | O18: TOTAL
D19: Talle Unico | E19: S | F19: M | G19: L
A20: 46101 | B20: Jersey Blanco Liso | C20: 1 | D20: 0 | E20: 1 | F20: 5 | G20: 4 | H20: 10 | I20: 30000 | J20: =SUM(I20*0.21) -> 6300 | K20: =SUM(I20:J20) -> 36300 | L20: =SUM(H20*K20) -> 363000 | M20: =SUM(H20*I20) -> 300000 | N20: 50000 | O20: =SUM(N20*H20) -> 500000
A21: 46101 | B21: Calza Negra Tria | C21: 2 | D21: 0 | E21: 2 | F21: 2 | G21: 4 | H21: 8 | I21: 30000 | J21: =SUM(I21*0.21) -> 6300 | K21: =SUM(I21:J21) -> 36300 | L21: =SUM(H21*K21) -> 290400 | M21: =SUM(H21*I21) -> 240000 | N21: 45000 | O21: =SUM(N21*H21) -> 360000
A22: 46101 | B22: Remera Verde Corta Femenina | C22: 3 | D22: 0 | E22: 6 | F22: 7 | G22: 7 | H22: =SUM(E22+F22+G22) -> 20 | I22: 15000 | J22: =SUM(I22*0.21) -> 3150 | K22: =SUM(I22:J22) -> 18150 | L22: =SUM(H22*K22) -> 363000 | M22: =SUM(H22*I22) -> 300000 | N22: 30000 | O22: =SUM(N22*H22) -> 600000
A23: 46101 | B23: Gorra Ciclista Sicodelica | C23: 4 | D23: 3 | E23: 0 | F23: 0 | G23: 0 | H23: 3 | I23: 5000 | J23: =SUM(I23*0.21) -> 1050 | K23: =SUM(I23:J23) -> 6050 | L23: =SUM(H23*K23) -> 18150 | M23: =SUM(H23*I23) -> 15000 | N23: 10000 | O23: =SUM(N23*H23) -> 30000
A24: 46101 | B24: Medias Ciclismo Blanca | C24: 5 | D24: 16 | E24: 0 | F24: 0 | G24: 0 | H24: 16 | I24: 4700 | J24: =SUM(I24*0.21) -> 987 | K24: =SUM(I24:J24) -> 5687 | L24: =SUM(H24*K24) -> 90992 | M24: =SUM(H24*I24) -> 75200 | N24: 7500 | O24: =SUM(N24*H24) -> 120000
A25: 46101 | B25: Medias Ciclismo Negra | C25: 6 | D25: 16 | E25: 0 | F25: 0 | G25: 0 | H25: 16 | I25: 4700 | J25: =SUM(I25*0.21) -> 987 | K25: =SUM(I25:J25) -> 5687 | L25: =SUM(H25*K25) -> 90992 | M25: =SUM(H25*I25) -> 75200 | N25: 7500 | O25: =SUM(N25*H25) -> 120000
A26: 46101 | B26: Porta Numeros | C26: 7 | D26: 10 | E26: 0 | F26: 0 | G26: 0 | H26: 10 | I26: 5000 | J26: =SUM(I26*0.21) -> 1050 | K26: =SUM(I26:J26) -> 6050 | L26: =SUM(H26*K26) -> 60500 | M26: =SUM(H26*I26) -> 50000 | N26: 10000 | O26: =SUM(N26*H26) -> 100000
I27: =SUM(I20:I26) -> 94400 | K27: =SUM(K20:K26) -> 114224 | L27: =SUM(L20:L26) -> 1277034 | M27: =SUM(M20:M26) -> 1055400 | N27: =SUM(N20:N26) -> 160000 | O27: =SUM(O19:O26) -> 1830000
A29: PEDIDOS GORRAS
A30: FECHA | B30: PRODUCTO | C30: CODIGO | D30: CANTIDAD | H30: CAN. TOTAL | I30: PCR | J30: IVA 21% | K30: PRECIO | L30: TOTAL C/IVA | M30: TOTAL S/IVA | N30: PRECIO VENTA | O30: TOTAL
D31: Talle Unico | E31: S | F31: M | G31: L | U31: REGALO | V31: STOCK
A32: 46101 | B32: Gorra deportiva Microfibra Blanca | D32: 10 | H32: 10 | I32: 5900 | J32: =SUM(I32*0.21) -> 1239 | K32: =SUM(I32:J32) -> 7139 | L32: =SUM(H32*K32) -> 71390 | M32: =SUM(H32*I32) -> 59000 | N32: 20000 | O32: =SUM(N32*H32) -> 200000 | U32: 6 | V32: =SUM(H32-(R32+S32+T32+U32)) -> 4
A33: 46101 | B33: Gorra deportiva Microfibra Negra | D33: 10 | H33: 10 | I33: 5900 | J33: =SUM(I33*0.21) -> 1239 | K33: =SUM(I33:J33) -> 7139 | L33: =SUM(H33*K33) -> 71390 | M33: =SUM(H33*I33) -> 59000 | N33: 20000 | O33: =SUM(N33*H33) -> 200000 | U33: 7 | V33: =SUM(H33-(R33+S33+T33+U33)) -> 3
A34: 46101 | B34: Gorra Gabardina Negra | D34: 5 | H34: 5 | I34: 6200 | J34: =SUM(I34*0.21) -> 1302 | K34: =SUM(I34:J34) -> 7502 | L34: =SUM(H34*K34) -> 37510 | M34: =SUM(H34*I34) -> 31000 | N34: 20000 | O34: =SUM(N34*H34) -> 100000 | U34: 2 | V34: =SUM(H34-(R34+S34+T34+U34)) -> 3
A35: 46101 | B35: Gorra Gabardina Blanca | D35: 5 | H35: 5 | I35: 6200 | J35: =SUM(I35*0.21) -> 1302 | K35: =SUM(I35:J35) -> 7502 | L35: =SUM(H35*K35) -> 37510 | M35: =SUM(H35*I35) -> 31000 | N35: 20000 | O35: =SUM(N35*H35) -> 100000 | U35: 2 | V35: =SUM(H35-(R35+S35+T35+U35)) -> 3
I36: =SUM(I32:I35) -> 24200 | K36: =SUM(K32:K35) -> 29282 | L36: =SUM(L32:L35) -> 217800 | M36: =SUM(M32:M35) -> 180000 | N36: =SUM(N32:N35) -> 80000 | O36: =SUM(O32:O35) -> 600000
A39: FECHA | B39: PRODUCTO | C39: CODIGO | D39: CANTIDAD | H39: CAN. TOTAL | I39: PCR | J39: IVA 21% | K39: PRECIO | L39: TOTAL C/IVA | M39: TOTAL S/IVA | N39: PRECIO VENTA | O39: TOTAL
D40: Talle Unico | E40: S | F40: M | G40: L
A41: 46101 | B41: Perchas Forradas Gamuza | D41: 50 | H41: 50 | I41: 900 | J41: =SUM(I41*0.21) -> 189 | K41: =SUM(I41:J41) -> 1089 | L41: =SUM(H41*K41) -> 54450 | M41: =SUM(H41*I41) -> 45000 | N41: 0 | O41: 0
A42: 46101 | B42: Perchas Forradas con broche | D42: 10 | H42: 10 | I42: 1300 | J42: =SUM(I42*0.21) -> 273 | K42: =SUM(I42:J42) -> 1573 | L42: =SUM(H42*K42) -> 15730 | M42: =SUM(H42*I42) -> 13000 | N42: 0 | O42: =SUM(N42*H42) -> 0
A43: 46101 | B43: Bolsas Negras 45x40 | D43: 100 | E43: 0 | F43: 0 | G43: 0 | H43: 100 | I43: 600 | J43: =SUM(I43*0.21) -> 126 | K43: =SUM(I43:J43) -> 726 | L43: =SUM(H43*K43) -> 72600 | M43: =SUM(H43*I43) -> 60000 | N43: 0 | O43: =SUM(N43*H43) -> 0
...

Sheet Precios
A2: PRODUCTO GARMONT | B2: S | C2: M | D2: L
A3: =Hoja1!B5 -> Bolso Logo TRIONX | E3: =Hoja1!N5 -> 140000
A4: =Hoja1!B6 -> Campera Pumori Hombre Negra | B4: 10 | C4: =Hoja1!F6 -> 14 | D4: =Hoja1!G6 -> 4 | E4: =Hoja1!N6 -> 260000
A5: =Hoja1!B7 -> Campera Pumori Hombre Roja | B5: 4 | C5: =Hoja1!F7 -> 6 | D5: =Hoja1!G7 -> 2 | E5: =Hoja1!N7 -> 260000
A6: =Hoja1!B8 -> Campera Pumori Mujer Negra | B6: 3 | C6: =Hoja1!F8 -> 3 | D6: =Hoja1!G8 -> 0 | E6: =Hoja1!N8 -> 260000
A7: =Hoja1!B9 -> Campera Pumori Mujer Salmon | B7: 3 | C7: =Hoja1!F9 -> 3 | D7: =Hoja1!G9 -> 0 | E7: =Hoja1!N9 -> 260000
A8: =Hoja1!B10 -> Remera Peñon Colorado Hombre Azul | B8: 1 | C8: =Hoja1!F10 -> 5 | D8: =Hoja1!G10 -> 2 | E8: =Hoja1!N10 -> 40000
A9: =Hoja1!B11 -> Remera Peñon Colorado Hombre Gris | B9: 1 | C9: =Hoja1!F11 -> 5 | D9: =Hoja1!G11 -> 2 | E9: =Hoja1!N11 -> 40000
A10: =Hoja1!B12 -> Remera Peñon Colorado Hombre terracota | B10: 2 | C10: =Hoja1!F12 -> 4 | D10: =Hoja1!G12 -> 2 | E10: =Hoja1!N12 -> 40000
A11: =Hoja1!B13 -> Remera Peñon Colorado Mujer Rosa | B11: 3 | C11: =Hoja1!F13 -> 4 | D11: =Hoja1!G13 -> 1 | E11: =Hoja1!N13 -> 40000
A12: =Hoja1!B14 -> Remera Peñon Colorado Mujer Gris | B12: 3 | C12: =Hoja1!F14 -> 4 | D12: =Hoja1!G14 -> 1 | E12: =Hoja1!N14 -> 40000
A13: =Hoja1!B15 -> Remera Peñon Colorado Mujer Terracota | B13: 3 | C13: =Hoja1!F15 -> 4 | D13: =Hoja1!G15 -> 1 | E13: =Hoja1!N15 -> 40000
A15: LINEA PISTA | B15: =Hoja1!E18 -> 0 | C15: =Hoja1!F18 -> 0 | D15: =Hoja1!G18 -> 0
A16: =Hoja1!B20 -> Jersey Blanco Liso | B16: =Hoja1!E19 -> S | C16: =Hoja1!F19 -> M | D16: =Hoja1!G19 -> L | E16: =Hoja1!N20 -> 50000
A17: =Hoja1!B21 -> Calza Negra Tria | B17: =Hoja1!E20 -> 1 | C17: =Hoja1!F20 -> 5 | D17: =Hoja1!G20 -> 4 | E17: =Hoja1!N21 -> 45000
A18: =Hoja1!B22 -> Remera Verde Corta Femenina | B18: =Hoja1!E21 -> 2 | C18: =Hoja1!F21 -> 2 | D18: =Hoja1!G21 -> 4 | E18: =Hoja1!N22 -> 30000
A19: =Hoja1!B23 -> Gorra Ciclista Sicodelica | B19: =Hoja1!E22 -> 6 | C19: =Hoja1!F22 -> 7 | D19: =Hoja1!G22 -> 7 | E19: =Hoja1!N23 -> 10000
A20: =Hoja1!B24 -> Medias Ciclismo Blanca | B20: =Hoja1!E23 -> 0 | C20: =Hoja1!F23 -> 0 | D20: =Hoja1!G23 -> 0 | E20: =Hoja1!N24 -> 7500
A21: =Hoja1!B25 -> Medias Ciclismo Negra | B21: =Hoja1!E24 -> 0 | C21: =Hoja1!F24 -> 0 | D21: =Hoja1!G24 -> 0 | E21: =Hoja1!N25 -> 7500
A22: =Hoja1!B26 -> Porta Numeros | B22: =Hoja1!E25 -> 0 | C22: =Hoja1!F25 -> 0 | D22: =Hoja1!G25 -> 0 | E22: =Hoja1!N26 -> 10000
A25: =Hoja1!B32 -> Gorra deportiva Microfibra Blanca | E25: =Hoja1!N32 -> 20000
A26: =Hoja1!B33 -> Gorra deportiva Microfibra Negra | E26: =Hoja1!N33 -> 20000
A27: =Hoja1!B34 -> Gorra Gabardina Negra | E27: =Hoja1!N34 -> 20000
A28: =Hoja1!B35 -> Gorra Gabardina Blanca | E28: =Hoja1!N35 -> 20000
